2020-10-11 17:15:59,115 ERROR: Exception on /favicon.ico [GET] [in c:\users\joseph staresinovic\appdata\local\programs\python\python38\lib\site-packages\flask\app.py:1891]
Traceback (most recent call last):
  File "c:\users\joseph staresinovic\appdata\local\programs\python\python38\lib\site-packages\flask\app.py", line 1950, in full_dispatch_request
    rv = self.dispatch_request()
  File "c:\users\joseph staresinovic\appdata\local\programs\python\python38\lib\site-packages\flask\app.py", line 1926, in dispatch_request
    self.raise_routing_exception(req)
  File "c:\users\joseph staresinovic\appdata\local\programs\python\python38\lib\site-packages\flask\app.py", line 1908, in raise_routing_exception
    raise request.routing_exception
  File "c:\users\joseph staresinovic\appdata\local\programs\python\python38\lib\site-packages\flask\ctx.py", line 350, in match_request
    result = self.url_adapter.match(return_rule=True)
  File "c:\users\joseph staresinovic\appdata\local\programs\python\python38\lib\site-packages\werkzeug\routing.py", line 1945, in match
    raise NotFound()
werkzeug.exceptions.NotFound: 404 Not Found: The requested URL was not found on the server. If you entered the URL manually please check your spelling and try again.

During handling of the above exception, another exception occurred:

Traceback (most recent call last):
  File "c:\users\joseph staresinovic\appdata\local\programs\python\python38\lib\site-packages\flask\app.py", line 2447, in wsgi_app
    response = self.full_dispatch_request()
  File "c:\users\joseph staresinovic\appdata\local\programs\python\python38\lib\site-packages\flask\app.py", line 1952, in full_dispatch_request
    rv = self.handle_user_exception(e)
  File "c:\users\joseph staresinovic\appdata\local\programs\python\python38\lib\site-packages\flask\app.py", line 1816, in handle_user_exception
    return self.handle_http_exception(e)
  File "c:\users\joseph staresinovic\appdata\local\programs\python\python38\lib\site-packages\flask\app.py", line 1744, in handle_http_exception
    return handler(e)
  File "C:\Users\Joseph Staresinovic\website\app\errors.py", line 7, in not_found_error
    return render_template('404.html'), 404
  File "c:\users\joseph staresinovic\appdata\local\programs\python\python38\lib\site-packages\flask\templating.py", line 138, in render_template
    ctx.app.jinja_env.get_or_select_template(template_name_or_list),
  File "c:\users\joseph staresinovic\appdata\local\programs\python\python38\lib\site-packages\jinja2\environment.py", line 930, in get_or_select_template
    return self.get_template(template_name_or_list, parent, globals)
  File "c:\users\joseph staresinovic\appdata\local\programs\python\python38\lib\site-packages\jinja2\environment.py", line 883, in get_template
    return self._load_template(name, self.make_globals(globals))
  File "c:\users\joseph staresinovic\appdata\local\programs\python\python38\lib\site-packages\jinja2\environment.py", line 857, in _load_template
    template = self.loader.load(self, name, globals)
  File "c:\users\joseph staresinovic\appdata\local\programs\python\python38\lib\site-packages\jinja2\loaders.py", line 115, in load
    source, filename, uptodate = self.get_source(environment, name)
  File "c:\users\joseph staresinovic\appdata\local\programs\python\python38\lib\site-packages\flask\templating.py", line 60, in get_source
    return self._get_source_fast(environment, template)
  File "c:\users\joseph staresinovic\appdata\local\programs\python\python38\lib\site-packages\flask\templating.py", line 89, in _get_source_fast
    raise TemplateNotFound(template)
jinja2.exceptions.TemplateNotFound: 404.html
2020-10-11 17:17:28,998 INFO: Serial Agony startup [in C:\Users\Joseph Staresinovic\website\app\__init__.py:57]
2020-10-11 17:50:49,141 INFO: Serial Agony startup [in C:\Users\Joseph Staresinovic\website\app\__init__.py:57]
2020-10-11 17:51:05,995 INFO: Serial Agony startup [in C:\Users\Joseph Staresinovic\website\app\__init__.py:57]
2020-10-12 13:39:04,892 INFO: Serial Agony startup [in C:\Users\Joseph Staresinovic\website\app\__init__.py:64]
2020-10-12 13:39:23,775 INFO: Serial Agony startup [in C:\Users\Joseph Staresinovic\website\app\__init__.py:64]
2020-10-12 13:51:57,803 INFO: Serial Agony startup [in C:\Users\Joseph Staresinovic\website\app\__init__.py:64]
2020-10-12 15:37:29,615 INFO: Serial Agony startup [in C:\Users\Joseph Staresinovic\website\app\__init__.py:64]
2020-10-12 15:39:56,825 INFO: Serial Agony startup [in C:\Users\Joseph Staresinovic\website\app\__init__.py:64]
2020-10-12 17:27:58,799 INFO: Serial Agony startup [in C:\Users\Joseph Staresinovic\website\app\__init__.py:64]
2020-10-12 17:28:20,496 INFO: Serial Agony startup [in C:\Users\Joseph Staresinovic\website\app\__init__.py:64]
2020-10-12 19:15:54,423 INFO: Serial Agony startup [in C:\Users\Joseph Staresinovic\website\app\__init__.py:59]
2020-10-12 19:16:03,077 ERROR: Exception on /index [GET] [in c:\users\joseph staresinovic\appdata\local\programs\python\python38\lib\site-packages\flask\app.py:1891]
Traceback (most recent call last):
  File "c:\users\joseph staresinovic\appdata\local\programs\python\python38\lib\site-packages\flask\app.py", line 2447, in wsgi_app
    response = self.full_dispatch_request()
  File "c:\users\joseph staresinovic\appdata\local\programs\python\python38\lib\site-packages\flask\app.py", line 1952, in full_dispatch_request
    rv = self.handle_user_exception(e)
  File "c:\users\joseph staresinovic\appdata\local\programs\python\python38\lib\site-packages\flask\app.py", line 1821, in handle_user_exception
    reraise(exc_type, exc_value, tb)
  File "c:\users\joseph staresinovic\appdata\local\programs\python\python38\lib\site-packages\flask\_compat.py", line 39, in reraise
    raise value
  File "c:\users\joseph staresinovic\appdata\local\programs\python\python38\lib\site-packages\flask\app.py", line 1950, in full_dispatch_request
    rv = self.dispatch_request()
  File "c:\users\joseph staresinovic\appdata\local\programs\python\python38\lib\site-packages\flask\app.py", line 1936, in dispatch_request
    return self.view_functions[rule.endpoint](**req.view_args)
  File "c:\users\joseph staresinovic\appdata\local\programs\python\python38\lib\site-packages\flask_login\utils.py", line 272, in decorated_view
    return func(*args, **kwargs)
  File "C:\Users\Joseph Staresinovic\website\app\routes.py", line 49, in index
    return render_template('index.html', title='Home', form=form,
  File "c:\users\joseph staresinovic\appdata\local\programs\python\python38\lib\site-packages\flask\templating.py", line 137, in render_template
    return _render(
  File "c:\users\joseph staresinovic\appdata\local\programs\python\python38\lib\site-packages\flask\templating.py", line 120, in _render
    rv = template.render(context)
  File "c:\users\joseph staresinovic\appdata\local\programs\python\python38\lib\site-packages\jinja2\environment.py", line 1090, in render
    self.environment.handle_exception()
  File "c:\users\joseph staresinovic\appdata\local\programs\python\python38\lib\site-packages\jinja2\environment.py", line 832, in handle_exception
    reraise(*rewrite_traceback_stack(source=source))
  File "c:\users\joseph staresinovic\appdata\local\programs\python\python38\lib\site-packages\jinja2\_compat.py", line 28, in reraise
    raise value.with_traceback(tb)
  File "C:\Users\Joseph Staresinovic\website\templates\index.html", line 1, in top-level template code
    {% extends "base.html" %}
  File "C:\Users\Joseph Staresinovic\website\templates\base.html", line 1, in top-level template code
    {% extends 'bootstrap/base.html' %}
  File "c:\users\joseph staresinovic\appdata\local\programs\python\python38\lib\site-packages\flask_bootstrap\templates\bootstrap\base.html", line 1, in top-level template code
    {% block doc -%}
  File "c:\users\joseph staresinovic\appdata\local\programs\python\python38\lib\site-packages\flask_bootstrap\templates\bootstrap\base.html", line 4, in block "doc"
    {%- block html %}
  File "c:\users\joseph staresinovic\appdata\local\programs\python\python38\lib\site-packages\flask_bootstrap\templates\bootstrap\base.html", line 20, in block "html"
    {% block body -%}
  File "c:\users\joseph staresinovic\appdata\local\programs\python\python38\lib\site-packages\flask_bootstrap\templates\bootstrap\base.html", line 21, in block "body"
    {% block navbar %}
  File "C:\Users\Joseph Staresinovic\website\templates\base.html", line 26, in block "navbar"
    action="{{ url_for('main.search') }}">
  File "c:\users\joseph staresinovic\appdata\local\programs\python\python38\lib\site-packages\flask\helpers.py", line 370, in url_for
    return appctx.app.handle_url_build_error(error, endpoint, values)
  File "c:\users\joseph staresinovic\appdata\local\programs\python\python38\lib\site-packages\flask\app.py", line 2216, in handle_url_build_error
    reraise(exc_type, exc_value, tb)
  File "c:\users\joseph staresinovic\appdata\local\programs\python\python38\lib\site-packages\flask\_compat.py", line 39, in reraise
    raise value
  File "c:\users\joseph staresinovic\appdata\local\programs\python\python38\lib\site-packages\flask\helpers.py", line 357, in url_for
    rv = url_adapter.build(
  File "c:\users\joseph staresinovic\appdata\local\programs\python\python38\lib\site-packages\werkzeug\routing.py", line 2179, in build
    raise BuildError(endpoint, values, method, self)
werkzeug.routing.BuildError: Could not build url for endpoint 'main.search'. Did you mean 'user' instead?
2020-10-12 19:22:48,981 INFO: Serial Agony startup [in C:\Users\Joseph Staresinovic\website\app\__init__.py:59]
